<?xml version="1.0" ?>
<robot name="push_robot" xmlns:xacro="http://ros.org/wiki/xacro">
  <!-- <xacro:include filename="$(find ssabot)/urdf/common_properties.xacro"/> -->
  <xacro:include filename="$(find ssabot)/urdf/push_robot.gazebo.xacro" />
  <material name="black">
    <color rgba="0.0 0.0 0.0 1.0"/>
  </material>

  <link name="world"/>

  <joint name="base_joint" type="fixed">
    <parent link="world"/>
    <child link="base_link" />
    <origin xyz="0 0 -0.5" rpy="0 0 0"/>
  </joint>

  <link name="base_link">
    <visual>
      <origin xyz="0 0 0" rpy="0 0 1.57"/>
      <geometry>
        <mesh filename="package://ssabot/meshes/wall.dae" scale="1 1 1"/>
        <!-- <box size="0.5 1 0.01"/> -->
      </geometry>
    </visual>

    <collision>
      <origin xyz="0 0 0.2" rpy="0 0 1.57"/>
      <geometry>
        <mesh filename="package://ssabot/meshes/wall.dae" scale="1 1 1"/>
      </geometry>
    </collision>

    <inertial>
      <origin xyz="0 0 0" rpy="0 0 0"/>
      <mass value="1.3729096e+02"/>
      <inertia ixx="8.7002718e-03" ixy="-4.7576583e-05" ixz="1.1160499e-04"
               iyy="8.6195418e-03" iyz="-3.5422299e-06"
               izz="1.4612727e-02" />
    </inertial>
  </link>

   <joint name="virtual_joint1" type="prismatic">
    <parent link="base_link"/>
    <child link="virtual_link1"/>
    <origin xyz="0 0 1" rpy="0 0 0"/>
    <axis xyz="0 1 0"/>
    <limit effort="0.185" lower="-1" upper="1" velocity="0.001"/>
  </joint>

  <link name="virtual_link1">
    <visual>
      <origin xyz="0 0 0" rpy="0 0 0"/>
      <geometry>
        <cylinder length="1.8" radius="0.05"/>
      </geometry>
    </visual>

    <!-- <collision>
      <origin xyz="0 0 0.3" rpy="0 0 0"/>
      <geometry>
          <box size="0.1 0.1 0.1"/>
      </geometry>
    </collision> -->
    
    <inertial>
      <origin xyz="0 0 0" rpy="0 0 0"/>
      <mass value="1.3729096e-05"/>
      <inertia ixx="8.7002718e-03" ixy="-4.7576583e-05" ixz="1.1160499e-04"
               iyy="8.6195418e-03" iyz="-3.5422299e-06"
               izz="1.4612727e-02" />
    </inertial>
  </link>

  <joint name="virtual_joint2" type="prismatic">
    <parent link="base_link"/>
    <child link="virtual_link2"/>
    <origin xyz="0 0 1" rpy="0 0 0"/>
    <axis xyz="0 0 1"/>
    <limit effort="0.03" lower="-0.5" upper="0.5" velocity="0.0001"/>
  </joint>

  <link name="virtual_link2">
    <visual>
      <origin xyz="0 0 0" rpy="-1.57 0 0"/>
      <geometry>
        <cylinder length="1.8" radius="0.05"/>
      </geometry>
    </visual>
    
    <inertial>
      <origin xyz="0 0 0" rpy="-1.57 0 0"/>
      <mass value="1.3729096e-05"/>
      <inertia ixx="8.7002718e-03" ixy="-4.7576583e-05" ixz="1.1160499e-04"
               iyy="8.6195418e-03" iyz="-3.5422299e-06"
               izz="1.4612727e-02" />
    </inertial>
  </link>

  <joint name="push_joint1" type="prismatic">
    <parent link="virtual_link1"/>
    <child link="push_link1"/>
    <origin xyz="0 0 0" rpy="0 0 0"/>
    <axis xyz="0 0 1"/>
    <limit effort="0.03" lower="-0.5" upper="0.5" velocity="0.0001"/>
  </joint>

  <link name="push_link1">
    <visual>
      <origin xyz="0 0 0" rpy="0 1.57 0"/>
      <geometry>
        <cylinder length="0.1" radius="0.2"/>
      </geometry>
    </visual>

    <!-- <collision>
      <origin xyz="0 0 0.05" rpy="0 0 0"/>
      <geometry>
          <box size="0.1 0.1 0.1"/>
      </geometry>
    </collision> -->
    
    <inertial>
      <origin xyz="0 0 0" rpy="0 0 0"/>
      <mass value="1.3729096e-05"/>
      <inertia ixx="8.7002718e-03" ixy="-4.7576583e-05" ixz="1.1160499e-04"
               iyy="8.6195418e-03" iyz="-3.5422299e-06"
               izz="1.4612727e-02" />
    </inertial>
  </link>

  <joint name="push_joint2" type="prismatic">
    <parent link="push_link1"/>
    <child link="push_link2"/>
    <origin xyz="0 0 0" rpy="0 0 0"/>
    <axis xyz="1 0 0"/>
    <limit effort="50" lower="-1" upper="1" velocity="0.01"/>
  </joint>

  <link name="push_link2">
    <visual>
      <origin xyz="0 0 0" rpy="0 1.57 0"/>
      <geometry>
        <cylinder length="0.18" radius="0.1"/>
      </geometry>
    </visual>

    <collision>
      <origin xyz="0 0 0" rpy="0 1.57 0"/>
      <geometry>
        <cylinder length="0.18" radius="0.15"/>
      </geometry>
    </collision>
    
    <inertial>
      <origin xyz="0 0 0" rpy="0 0 0"/>
      <mass value="1.3729096e-05"/>
      <inertia ixx="8.7002718e-03" ixy="-4.7576583e-05" ixz="1.1160499e-04"
               iyy="8.6195418e-03" iyz="-3.5422299e-06"
               izz="1.4612727e-02" />
    </inertial>
  </link>

  <!-- <transmission name="actuator1">
    <type>transmission_interface/SimpleTransmission</type>
    <joint name="virtual_joint1">
      <hardwareInterface>hardware_interface/EffortJointInterface</hardwareInterface>
    </joint>
    <actuator name="push_motor1">
      <hardwareInterface>hardware_interface/EffortJointInterface</hardwareInterface>
      <mechanicalReduction>1</mechanicalReduction>
    </actuator>
  </transmission> -->

  
  <!--  -->


  <!-- <link name="piston_link2">
    <visual>
	  <origin xyz="0 0 0.05" rpy="0 0 0"/>
      <geometry>
        <cylinder length="0.02" radius="0.01"/>
      </geometry>
      <material name="orange"/>
    </visual>
    <inertial>
      <origin xyz="0 0 0" rpy="0 0 0"/>
      <mass value="0.001"/>
      <inertia ixx="0.0" ixy="0.0" ixz="0.0" iyy="0.0" iyz="0.0" izz="0.0"/>
    </inertial>
  </link>

  <joint name="piston_joint3" type="fixed">
    <parent link="piston_link2"/>
    <child link="piston_plate"/>
  </joint>

  <link name="piston_plate">
    <visual>
      <origin xyz="-0.05 0 0.17" rpy="0 0 1.57"/>
      <geometry>
        <mesh filename="package://ssabot/meshes/piston/piston_plate.dae" scale="0.015 0.015 0.015"/>
      </geometry>
      <material name="dark"/>
    </visual>

    <collision>
      <origin xyz="-0.05 0 0.17" rpy="0 0 1.57"/>
      <geometry>
        <mesh filename="package://ssabot/meshes/piston/piston_plate.dae" scale="0.015 0.015 0.015"/>
      </geometry>
    </collision>
  </link -->

  <!-- <transmission name="waffle_tran">
    <type>transmission_interface/SimpleTransmission</type>
    <joint name="piston_joint2">
      <hardwareInterface>hardware_interface/PositionJointInterface</hardwareInterface>
    </joint>
    <actuator name="waffle_motor">
      <hardwareInterface>hardware_interface/PositionJointInterface</hardwareInterface>
      <mechanicalReduction>1</mechanicalReduction>
    </actuator>
  </transmission> -->

</robot>

  <!-- <joint name="piston_joint2" type="prismatic">
    <parent link="piston_link1"/>
    <child link="piston_link2"/>
    <origin xyz="0 0 0.05" rpy="0 0 0"/>
    <axis xyz="0 0 1"/>
    <limit effort="30" lower="-0.1" upper="0.1" velocity="0.171"/>
  </joint> -->