<?xml version="1.0" ?>
<robot name="turtlebot3_burger" xmlns:xacro="http://ros.org/wiki/xacro">
  <xacro:include filename="$(find ssabot)/urdf/common_properties.xacro"/>
  <xacro:include filename="$(find ssabot)/urdf/turtlebot3_burger.gazebo.xacro"/>

  <link name="base_footprint"/>

  <joint name="base_joint" type="fixed">
    <parent link="base_footprint"/>
    <child link="base_link"/>
    <origin xyz="0.0 0.0 0.020" rpy="0 0 0"/>
  </joint>

  <link name="base_link">
    <visual>
      <origin xyz="-0.064 0 0.0" rpy="0 0 0"/>
      <geometry>
        <mesh filename="package://ssabot/meshes/bases/burger_base.stl" scale="0.002 0.002 0.002"/>
      </geometry>
      <material name="light_black"/>
    </visual>

    <collision>
      <origin xyz="-0.064 0 0.140" rpy="0 0 0"/>
      <geometry>
        <box size="0.280 0.280 0.286"/>
      </geometry>
    </collision>

    <inertial>
      <origin xyz="0 0 0" rpy="0 0 0"/>
      <mass value="8.2573504e-01"/>
      <inertia ixx="2.2124416e-03" ixy="-1.2294101e-05" ixz="3.4938785e-05"
               iyy="2.1193702e-03" iyz="-5.0120904e-06"
               izz="2.0064271e-03" />
    </inertial>
  </link>

  <joint name="wheel_left_joint" type="continuous">
    <parent link="base_link"/>
    <child link="wheel_left_link"/>
    <origin xyz="0.0 0.16 0.046" rpy="-1.57 0 0"/>
    <axis xyz="0 0 1"/>
  </joint>

  <link name="wheel_left_link">
    <visual>
      <origin xyz="0 0 0" rpy="1.57 0 0"/>
      <geometry>
        <mesh filename="package://ssabot/meshes/wheels/left_tire.stl" scale="0.002 0.002 0.002"/>
      </geometry>
      <material name="dark"/>
    </visual>

    <collision>
      <origin xyz="0 0 0" rpy="0 0 0"/>
      <geometry>
        <cylinder length="0.036" radius="0.066"/>
      </geometry>
    </collision>

    <inertial>
      <origin xyz="0 0 0" />
      <mass value="5.6398940e-02" />
      <inertia ixx="2.1175580e-05" ixy="-8.2369783e-11" ixz="-10.9381719e-09"
               iyy="2.1192413e-05" iyz="-2.4400107e-11"
               izz="4.0712558e-05" />
    </inertial>
  </link>

  <joint name="wheel_right_joint" type="continuous">
    <parent link="base_link"/>
    <child link="wheel_right_link"/>
    <origin xyz="0.0 -0.160 0.046" rpy="-1.57 0 0"/>
    <axis xyz="0 0 1"/>
  </joint>

  <link name="wheel_right_link">
    <visual>
      <origin xyz="0 0 0" rpy="1.57 0 0"/>
      <geometry>
        <mesh filename="package://ssabot/meshes/wheels/right_tire.stl" scale="0.002 0.002 0.002"/>
      </geometry>
      <material name="dark"/>
    </visual>

    <collision>
      <origin xyz="0 0 0" rpy="0 0 0"/>
      <geometry>
        <cylinder length="0.036" radius="0.066"/>
      </geometry>
    </collision>

    <inertial>
      <origin xyz="0 0 0" />
      <mass value="5.6398940e-02" />
      <inertia ixx="2.1175580e-05" ixy="-8.2369783e-11" ixz="-10.9381719e-09"
               iyy="2.1192413e-05" iyz="-2.4400107e-11"
               izz="4.0712558e-05" />
      </inertial>
  </link>

  <joint name="caster_back_joint" type="fixed">
    <parent link="base_link"/>
    <child link="caster_back_link"/>
    <origin xyz="-0.162 0 -0.008" rpy="-1.57 0 0"/>
  </joint>

  <link name="caster_back_link">
    <collision>
      <origin xyz="0 0.002 0" rpy="0 0 0"/>
      <geometry>
        <box size="0.060 0.018 0.040"/>
      </geometry>
    </collision>

    <inertial>
      <origin xyz="0 0 0" />
      <mass value="0.010" />
      <inertia ixx="0.002" ixy="0.0" ixz="0.0"
               iyy="0.002" iyz="0.0"
               izz="0.002" />
    </inertial>
  </link>

  <joint name="imu_joint" type="fixed">
    <parent link="base_link"/>
    <child link="imu_link"/>
    <origin xyz="-0.032 0 0.068" rpy="0 0 0"/>
  </joint>

  <link name="imu_link"/>

  <joint name="dump_joint" type="revolute">
    <parent link="base_link"/>
    <child link="dumper_bin"/>
    <origin xyz="0.2 0 0.28" rpy="0 0 0"/>
    <axis xyz="0 1 0"/>
    <limit effort="1" velocity="1" lower="0" upper="0.6"/>
  </joint>

  <!-- <link name="dumper_bin">

    <collision name='collision'>
      <origin xyz="-0.15 0 0" rpy=" 0 0 1.57079"/> 
        <geometry>
          <box size="0.3 0.3 0.01"/>
        </geometry>
    </collision>
    <visual name='dump_box_visual'>
      <origin xyz=" -0.15 0 0.0" rpy="0 0 1.57079"/>
        <geometry>
          <box size="0.3 0.3 0.01"/>
        </geometry>
    </visual>

    <inertial>
      <mass value="0.0001" />
      <origin xyz="0 0 0" />
      <inertia ixx="0.001" ixy="0.0" ixz="0.0"
               iyy="0.001" iyz="0.0"
               izz="0.001" />
    </inertial>
  </link> -->

  <link name="dumper_bin">

    <collision name='collision'>
      <origin xyz="-0.3 0 0" rpy=" 0 0 1.57079"/> 
        <geometry>
          <mesh filename="package://ssabot/meshes/meshes/dumper_bin.dae" scale="0.013 0.013 0.013"/>
        </geometry>
    </collision>
    <visual >
      <origin xyz=" -0.3 0 0.0" rpy="0 0 1.57079"/>
        <geometry>
          <mesh filename="package://ssabot/meshes/meshes/dumper_bin.dae" scale="0.013 0.013 0.013"/>
        </geometry>
    </visual>

    <inertial>
      <mass value="0.001" />
      <origin xyz="0 0 0" />
      <inertia ixx="0.001" ixy="0.0" ixz="0.0"
               iyy="0.001" iyz="0.0"
               izz="0.001" />
    </inertial>
  </link>

</robot>